2025-09-12 08:06:49,976 - conftest - INFO - Инициализация WebDriver
2025-09-12 08:18:53,500 - conftest - ERROR - Тест test_check_center_text_after_navigation упал с ошибкой: /opt/hostedtoolcache/Python/3.11.13/x64/lib/python3.11/site-packages/urllib3/connectionpool.py:534: in _make_request
    response = conn.getresponse()
               ^^^^^^^^^^^^^^^^^^
/opt/hostedtoolcache/Python/3.11.13/x64/lib/python3.11/site-packages/urllib3/connection.py:565: in getresponse
    httplib_response = super().getresponse()
                       ^^^^^^^^^^^^^^^^^^^^^
/opt/hostedtoolcache/Python/3.11.13/x64/lib/python3.11/http/client.py:1395: in getresponse
    response.begin()
/opt/hostedtoolcache/Python/3.11.13/x64/lib/python3.11/http/client.py:325: in begin
    version, status, reason = self._read_status()
                              ^^^^^^^^^^^^^^^^^^^
/opt/hostedtoolcache/Python/3.11.13/x64/lib/python3.11/http/client.py:286: in _read_status
    line = str(self.fp.readline(_MAXLINE + 1), "iso-8859-1")
               ^^^^^^^^^^^^^^^^^^^^^^^^^^^^^^
/opt/hostedtoolcache/Python/3.11.13/x64/lib/python3.11/socket.py:718: in readinto
    return self._sock.recv_into(b)
           ^^^^^^^^^^^^^^^^^^^^^^^
E   TimeoutError: timed out

The above exception was the direct cause of the following exception:
pages/demoqa_page.py:110: in click_elements_button
    WebDriverWait(self.driver, 15).until(
/opt/hostedtoolcache/Python/3.11.13/x64/lib/python3.11/site-packages/selenium/webdriver/support/wait.py:129: in until
    value = method(self._driver)
            ^^^^^^^^^^^^^^^^^^^^
/opt/hostedtoolcache/Python/3.11.13/x64/lib/python3.11/site-packages/selenium/webdriver/support/expected_conditions.py:104: in _predicate
    return driver.find_element(*locator)
           ^^^^^^^^^^^^^^^^^^^^^^^^^^^^^
/opt/hostedtoolcache/Python/3.11.13/x64/lib/python3.11/site-packages/selenium/webdriver/remote/webdriver.py:926: in find_element
    return self.execute(Command.FIND_ELEMENT, {"using": by, "value": value})["value"]
           ^^^^^^^^^^^^^^^^^^^^^^^^^^^^^^^^^^^^^^^^^^^^^^^^^^^^^^^^^^^^^^^^^
/opt/hostedtoolcache/Python/3.11.13/x64/lib/python3.11/site-packages/selenium/webdriver/remote/webdriver.py:455: in execute
    response = cast(RemoteConnection, self.command_executor).execute(driver_command, params)
               ^^^^^^^^^^^^^^^^^^^^^^^^^^^^^^^^^^^^^^^^^^^^^^^^^^^^^^^^^^^^^^^^^^^^^^^^^^^^^
/opt/hostedtoolcache/Python/3.11.13/x64/lib/python3.11/site-packages/selenium/webdriver/remote/remote_connection.py:406: in execute
    return self._request(command_info[0], url, body=data)
           ^^^^^^^^^^^^^^^^^^^^^^^^^^^^^^^^^^^^^^^^^^^^^^
/opt/hostedtoolcache/Python/3.11.13/x64/lib/python3.11/site-packages/selenium/webdriver/remote/remote_connection.py:430: in _request
    response = self._conn.request(method, url, body=body, headers=headers, timeout=self._client_config.timeout)
               ^^^^^^^^^^^^^^^^^^^^^^^^^^^^^^^^^^^^^^^^^^^^^^^^^^^^^^^^^^^^^^^^^^^^^^^^^^^^^^^^^^^^^^^^^^^^^^^^
/opt/hostedtoolcache/Python/3.11.13/x64/lib/python3.11/site-packages/urllib3/_request_methods.py:143: in request
    return self.request_encode_body(
/opt/hostedtoolcache/Python/3.11.13/x64/lib/python3.11/site-packages/urllib3/_request_methods.py:278: in request_encode_body
    return self.urlopen(method, url, **extra_kw)
           ^^^^^^^^^^^^^^^^^^^^^^^^^^^^^^^^^^^^^
/opt/hostedtoolcache/Python/3.11.13/x64/lib/python3.11/site-packages/urllib3/poolmanager.py:459: in urlopen
    response = conn.urlopen(method, u.request_uri, **kw)
               ^^^^^^^^^^^^^^^^^^^^^^^^^^^^^^^^^^^^^^^^^
/opt/hostedtoolcache/Python/3.11.13/x64/lib/python3.11/site-packages/urllib3/connectionpool.py:841: in urlopen
    retries = retries.increment(
/opt/hostedtoolcache/Python/3.11.13/x64/lib/python3.11/site-packages/urllib3/util/retry.py:474: in increment
    raise reraise(type(error), error, _stacktrace)
          ^^^^^^^^^^^^^^^^^^^^^^^^^^^^^^^^^^^^^^^^
/opt/hostedtoolcache/Python/3.11.13/x64/lib/python3.11/site-packages/urllib3/util/util.py:39: in reraise
    raise value
/opt/hostedtoolcache/Python/3.11.13/x64/lib/python3.11/site-packages/urllib3/connectionpool.py:787: in urlopen
    response = self._make_request(
/opt/hostedtoolcache/Python/3.11.13/x64/lib/python3.11/site-packages/urllib3/connectionpool.py:536: in _make_request
    self._raise_timeout(err=e, url=url, timeout_value=read_timeout)
/opt/hostedtoolcache/Python/3.11.13/x64/lib/python3.11/site-packages/urllib3/connectionpool.py:367: in _raise_timeout
    raise ReadTimeoutError(
E   urllib3.exceptions.ReadTimeoutError: HTTPConnectionPool(host='localhost', port=48727): Read timed out. (read timeout=120)

During handling of the above exception, another exception occurred:
/opt/hostedtoolcache/Python/3.11.13/x64/lib/python3.11/site-packages/urllib3/connectionpool.py:534: in _make_request
    response = conn.getresponse()
               ^^^^^^^^^^^^^^^^^^
/opt/hostedtoolcache/Python/3.11.13/x64/lib/python3.11/site-packages/urllib3/connection.py:565: in getresponse
    httplib_response = super().getresponse()
                       ^^^^^^^^^^^^^^^^^^^^^
/opt/hostedtoolcache/Python/3.11.13/x64/lib/python3.11/http/client.py:1395: in getresponse
    response.begin()
/opt/hostedtoolcache/Python/3.11.13/x64/lib/python3.11/http/client.py:325: in begin
    version, status, reason = self._read_status()
                              ^^^^^^^^^^^^^^^^^^^
/opt/hostedtoolcache/Python/3.11.13/x64/lib/python3.11/http/client.py:286: in _read_status
    line = str(self.fp.readline(_MAXLINE + 1), "iso-8859-1")
               ^^^^^^^^^^^^^^^^^^^^^^^^^^^^^^
/opt/hostedtoolcache/Python/3.11.13/x64/lib/python3.11/socket.py:718: in readinto
    return self._sock.recv_into(b)
           ^^^^^^^^^^^^^^^^^^^^^^^
E   TimeoutError: timed out

The above exception was the direct cause of the following exception:
tests/test_check_text.py:60: in test_check_center_text_after_navigation
    demoqa_page.click_elements_button()
pages/demoqa_page.py:123: in click_elements_button
    self.driver.get("https://demoqa.com/elements")
/opt/hostedtoolcache/Python/3.11.13/x64/lib/python3.11/site-packages/selenium/webdriver/remote/webdriver.py:483: in get
    self.execute(Command.GET, {"url": url})
/opt/hostedtoolcache/Python/3.11.13/x64/lib/python3.11/site-packages/selenium/webdriver/remote/webdriver.py:455: in execute
    response = cast(RemoteConnection, self.command_executor).execute(driver_command, params)
               ^^^^^^^^^^^^^^^^^^^^^^^^^^^^^^^^^^^^^^^^^^^^^^^^^^^^^^^^^^^^^^^^^^^^^^^^^^^^^
/opt/hostedtoolcache/Python/3.11.13/x64/lib/python3.11/site-packages/selenium/webdriver/remote/remote_connection.py:406: in execute
    return self._request(command_info[0], url, body=data)
           ^^^^^^^^^^^^^^^^^^^^^^^^^^^^^^^^^^^^^^^^^^^^^^
/opt/hostedtoolcache/Python/3.11.13/x64/lib/python3.11/site-packages/selenium/webdriver/remote/remote_connection.py:430: in _request
    response = self._conn.request(method, url, body=body, headers=headers, timeout=self._client_config.timeout)
               ^^^^^^^^^^^^^^^^^^^^^^^^^^^^^^^^^^^^^^^^^^^^^^^^^^^^^^^^^^^^^^^^^^^^^^^^^^^^^^^^^^^^^^^^^^^^^^^^
/opt/hostedtoolcache/Python/3.11.13/x64/lib/python3.11/site-packages/urllib3/_request_methods.py:143: in request
    return self.request_encode_body(
/opt/hostedtoolcache/Python/3.11.13/x64/lib/python3.11/site-packages/urllib3/_request_methods.py:278: in request_encode_body
    return self.urlopen(method, url, **extra_kw)
           ^^^^^^^^^^^^^^^^^^^^^^^^^^^^^^^^^^^^^
/opt/hostedtoolcache/Python/3.11.13/x64/lib/python3.11/site-packages/urllib3/poolmanager.py:459: in urlopen
    response = conn.urlopen(method, u.request_uri, **kw)
               ^^^^^^^^^^^^^^^^^^^^^^^^^^^^^^^^^^^^^^^^^
/opt/hostedtoolcache/Python/3.11.13/x64/lib/python3.11/site-packages/urllib3/connectionpool.py:841: in urlopen
    retries = retries.increment(
/opt/hostedtoolcache/Python/3.11.13/x64/lib/python3.11/site-packages/urllib3/util/retry.py:474: in increment
    raise reraise(type(error), error, _stacktrace)
          ^^^^^^^^^^^^^^^^^^^^^^^^^^^^^^^^^^^^^^^^
/opt/hostedtoolcache/Python/3.11.13/x64/lib/python3.11/site-packages/urllib3/util/util.py:39: in reraise
    raise value
/opt/hostedtoolcache/Python/3.11.13/x64/lib/python3.11/site-packages/urllib3/connectionpool.py:787: in urlopen
    response = self._make_request(
/opt/hostedtoolcache/Python/3.11.13/x64/lib/python3.11/site-packages/urllib3/connectionpool.py:536: in _make_request
    self._raise_timeout(err=e, url=url, timeout_value=read_timeout)
/opt/hostedtoolcache/Python/3.11.13/x64/lib/python3.11/site-packages/urllib3/connectionpool.py:367: in _raise_timeout
    raise ReadTimeoutError(
E   urllib3.exceptions.ReadTimeoutError: HTTPConnectionPool(host='localhost', port=48727): Read timed out. (read timeout=120)

During handling of the above exception, another exception occurred:
/opt/hostedtoolcache/Python/3.11.13/x64/lib/python3.11/site-packages/urllib3/connectionpool.py:534: in _make_request
    response = conn.getresponse()
               ^^^^^^^^^^^^^^^^^^
/opt/hostedtoolcache/Python/3.11.13/x64/lib/python3.11/site-packages/urllib3/connection.py:565: in getresponse
    httplib_response = super().getresponse()
                       ^^^^^^^^^^^^^^^^^^^^^
/opt/hostedtoolcache/Python/3.11.13/x64/lib/python3.11/http/client.py:1395: in getresponse
    response.begin()
/opt/hostedtoolcache/Python/3.11.13/x64/lib/python3.11/http/client.py:325: in begin
    version, status, reason = self._read_status()
                              ^^^^^^^^^^^^^^^^^^^
/opt/hostedtoolcache/Python/3.11.13/x64/lib/python3.11/http/client.py:286: in _read_status
    line = str(self.fp.readline(_MAXLINE + 1), "iso-8859-1")
               ^^^^^^^^^^^^^^^^^^^^^^^^^^^^^^
/opt/hostedtoolcache/Python/3.11.13/x64/lib/python3.11/socket.py:718: in readinto
    return self._sock.recv_into(b)
           ^^^^^^^^^^^^^^^^^^^^^^^
E   TimeoutError: timed out

The above exception was the direct cause of the following exception:
/opt/hostedtoolcache/Python/3.11.13/x64/lib/python3.11/site-packages/urllib3/connectionpool.py:787: in urlopen
    response = self._make_request(
/opt/hostedtoolcache/Python/3.11.13/x64/lib/python3.11/site-packages/urllib3/connectionpool.py:536: in _make_request
    self._raise_timeout(err=e, url=url, timeout_value=read_timeout)
/opt/hostedtoolcache/Python/3.11.13/x64/lib/python3.11/site-packages/urllib3/connectionpool.py:367: in _raise_timeout
    raise ReadTimeoutError(
E   urllib3.exceptions.ReadTimeoutError: HTTPConnectionPool(host='localhost', port=48727): Read timed out. (read timeout=120)

The above exception was the direct cause of the following exception:
tests/test_check_text.py:85: in test_check_center_text_after_navigation
    logger.error(f"Current URL: {driver.current_url}")
                                 ^^^^^^^^^^^^^^^^^^
/opt/hostedtoolcache/Python/3.11.13/x64/lib/python3.11/site-packages/selenium/webdriver/remote/webdriver.py:587: in current_url
    return self.execute(Command.GET_CURRENT_URL)["value"]
           ^^^^^^^^^^^^^^^^^^^^^^^^^^^^^^^^^^^^^
/opt/hostedtoolcache/Python/3.11.13/x64/lib/python3.11/site-packages/selenium/webdriver/remote/webdriver.py:455: in execute
    response = cast(RemoteConnection, self.command_executor).execute(driver_command, params)
               ^^^^^^^^^^^^^^^^^^^^^^^^^^^^^^^^^^^^^^^^^^^^^^^^^^^^^^^^^^^^^^^^^^^^^^^^^^^^^
/opt/hostedtoolcache/Python/3.11.13/x64/lib/python3.11/site-packages/selenium/webdriver/remote/remote_connection.py:406: in execute
    return self._request(command_info[0], url, body=data)
           ^^^^^^^^^^^^^^^^^^^^^^^^^^^^^^^^^^^^^^^^^^^^^^
/opt/hostedtoolcache/Python/3.11.13/x64/lib/python3.11/site-packages/selenium/webdriver/remote/remote_connection.py:430: in _request
    response = self._conn.request(method, url, body=body, headers=headers, timeout=self._client_config.timeout)
               ^^^^^^^^^^^^^^^^^^^^^^^^^^^^^^^^^^^^^^^^^^^^^^^^^^^^^^^^^^^^^^^^^^^^^^^^^^^^^^^^^^^^^^^^^^^^^^^^
/opt/hostedtoolcache/Python/3.11.13/x64/lib/python3.11/site-packages/urllib3/_request_methods.py:135: in request
    return self.request_encode_url(
/opt/hostedtoolcache/Python/3.11.13/x64/lib/python3.11/site-packages/urllib3/_request_methods.py:182: in request_encode_url
    return self.urlopen(method, url, **extra_kw)
           ^^^^^^^^^^^^^^^^^^^^^^^^^^^^^^^^^^^^^
/opt/hostedtoolcache/Python/3.11.13/x64/lib/python3.11/site-packages/urllib3/poolmanager.py:459: in urlopen
    response = conn.urlopen(method, u.request_uri, **kw)
               ^^^^^^^^^^^^^^^^^^^^^^^^^^^^^^^^^^^^^^^^^
/opt/hostedtoolcache/Python/3.11.13/x64/lib/python3.11/site-packages/urllib3/connectionpool.py:871: in urlopen
    return self.urlopen(
/opt/hostedtoolcache/Python/3.11.13/x64/lib/python3.11/site-packages/urllib3/connectionpool.py:871: in urlopen
    return self.urlopen(
/opt/hostedtoolcache/Python/3.11.13/x64/lib/python3.11/site-packages/urllib3/connectionpool.py:871: in urlopen
    return self.urlopen(
/opt/hostedtoolcache/Python/3.11.13/x64/lib/python3.11/site-packages/urllib3/connectionpool.py:841: in urlopen
    retries = retries.increment(
/opt/hostedtoolcache/Python/3.11.13/x64/lib/python3.11/site-packages/urllib3/util/retry.py:519: in increment
    raise MaxRetryError(_pool, url, reason) from reason  # type: ignore[arg-type]
    ^^^^^^^^^^^^^^^^^^^^^^^^^^^^^^^^^^^^^^^^^^^^^^^^^^^
E   urllib3.exceptions.MaxRetryError: HTTPConnectionPool(host='localhost', port=48727): Max retries exceeded with url: /session/1d176248842fd57659669f84f245a503/url (Caused by ReadTimeoutError("HTTPConnectionPool(host='localhost', port=48727): Read timed out. (read timeout=120)"))
2025-09-12 08:27:03,814 - conftest - INFO - Завершение работы WebDriver
2025-09-12 08:27:05,817 - conftest - INFO - Инициализация WebDriver
2025-09-12 08:39:09,293 - conftest - ERROR - Тест test_check_center_text_after_navigation упал с ошибкой: /opt/hostedtoolcache/Python/3.11.13/x64/lib/python3.11/site-packages/urllib3/connectionpool.py:534: in _make_request
    response = conn.getresponse()
               ^^^^^^^^^^^^^^^^^^
/opt/hostedtoolcache/Python/3.11.13/x64/lib/python3.11/site-packages/urllib3/connection.py:565: in getresponse
    httplib_response = super().getresponse()
                       ^^^^^^^^^^^^^^^^^^^^^
/opt/hostedtoolcache/Python/3.11.13/x64/lib/python3.11/http/client.py:1395: in getresponse
    response.begin()
/opt/hostedtoolcache/Python/3.11.13/x64/lib/python3.11/http/client.py:325: in begin
    version, status, reason = self._read_status()
                              ^^^^^^^^^^^^^^^^^^^
/opt/hostedtoolcache/Python/3.11.13/x64/lib/python3.11/http/client.py:286: in _read_status
    line = str(self.fp.readline(_MAXLINE + 1), "iso-8859-1")
               ^^^^^^^^^^^^^^^^^^^^^^^^^^^^^^
/opt/hostedtoolcache/Python/3.11.13/x64/lib/python3.11/socket.py:718: in readinto
    return self._sock.recv_into(b)
           ^^^^^^^^^^^^^^^^^^^^^^^
E   TimeoutError: timed out

The above exception was the direct cause of the following exception:
pages/demoqa_page.py:110: in click_elements_button
    WebDriverWait(self.driver, 15).until(
/opt/hostedtoolcache/Python/3.11.13/x64/lib/python3.11/site-packages/selenium/webdriver/support/wait.py:129: in until
    value = method(self._driver)
            ^^^^^^^^^^^^^^^^^^^^
/opt/hostedtoolcache/Python/3.11.13/x64/lib/python3.11/site-packages/selenium/webdriver/support/expected_conditions.py:104: in _predicate
    return driver.find_element(*locator)
           ^^^^^^^^^^^^^^^^^^^^^^^^^^^^^
/opt/hostedtoolcache/Python/3.11.13/x64/lib/python3.11/site-packages/selenium/webdriver/remote/webdriver.py:926: in find_element
    return self.execute(Command.FIND_ELEMENT, {"using": by, "value": value})["value"]
           ^^^^^^^^^^^^^^^^^^^^^^^^^^^^^^^^^^^^^^^^^^^^^^^^^^^^^^^^^^^^^^^^^
/opt/hostedtoolcache/Python/3.11.13/x64/lib/python3.11/site-packages/selenium/webdriver/remote/webdriver.py:455: in execute
    response = cast(RemoteConnection, self.command_executor).execute(driver_command, params)
               ^^^^^^^^^^^^^^^^^^^^^^^^^^^^^^^^^^^^^^^^^^^^^^^^^^^^^^^^^^^^^^^^^^^^^^^^^^^^^
/opt/hostedtoolcache/Python/3.11.13/x64/lib/python3.11/site-packages/selenium/webdriver/remote/remote_connection.py:406: in execute
    return self._request(command_info[0], url, body=data)
           ^^^^^^^^^^^^^^^^^^^^^^^^^^^^^^^^^^^^^^^^^^^^^^
/opt/hostedtoolcache/Python/3.11.13/x64/lib/python3.11/site-packages/selenium/webdriver/remote/remote_connection.py:430: in _request
    response = self._conn.request(method, url, body=body, headers=headers, timeout=self._client_config.timeout)
               ^^^^^^^^^^^^^^^^^^^^^^^^^^^^^^^^^^^^^^^^^^^^^^^^^^^^^^^^^^^^^^^^^^^^^^^^^^^^^^^^^^^^^^^^^^^^^^^^
/opt/hostedtoolcache/Python/3.11.13/x64/lib/python3.11/site-packages/urllib3/_request_methods.py:143: in request
    return self.request_encode_body(
/opt/hostedtoolcache/Python/3.11.13/x64/lib/python3.11/site-packages/urllib3/_request_methods.py:278: in request_encode_body
    return self.urlopen(method, url, **extra_kw)
           ^^^^^^^^^^^^^^^^^^^^^^^^^^^^^^^^^^^^^
/opt/hostedtoolcache/Python/3.11.13/x64/lib/python3.11/site-packages/urllib3/poolmanager.py:459: in urlopen
    response = conn.urlopen(method, u.request_uri, **kw)
               ^^^^^^^^^^^^^^^^^^^^^^^^^^^^^^^^^^^^^^^^^
/opt/hostedtoolcache/Python/3.11.13/x64/lib/python3.11/site-packages/urllib3/connectionpool.py:841: in urlopen
    retries = retries.increment(
/opt/hostedtoolcache/Python/3.11.13/x64/lib/python3.11/site-packages/urllib3/util/retry.py:474: in increment
    raise reraise(type(error), error, _stacktrace)
          ^^^^^^^^^^^^^^^^^^^^^^^^^^^^^^^^^^^^^^^^
/opt/hostedtoolcache/Python/3.11.13/x64/lib/python3.11/site-packages/urllib3/util/util.py:39: in reraise
    raise value
/opt/hostedtoolcache/Python/3.11.13/x64/lib/python3.11/site-packages/urllib3/connectionpool.py:787: in urlopen
    response = self._make_request(
/opt/hostedtoolcache/Python/3.11.13/x64/lib/python3.11/site-packages/urllib3/connectionpool.py:536: in _make_request
    self._raise_timeout(err=e, url=url, timeout_value=read_timeout)
/opt/hostedtoolcache/Python/3.11.13/x64/lib/python3.11/site-packages/urllib3/connectionpool.py:367: in _raise_timeout
    raise ReadTimeoutError(
E   urllib3.exceptions.ReadTimeoutError: HTTPConnectionPool(host='localhost', port=59449): Read timed out. (read timeout=120)

During handling of the above exception, another exception occurred:
/opt/hostedtoolcache/Python/3.11.13/x64/lib/python3.11/site-packages/urllib3/connectionpool.py:534: in _make_request
    response = conn.getresponse()
               ^^^^^^^^^^^^^^^^^^
/opt/hostedtoolcache/Python/3.11.13/x64/lib/python3.11/site-packages/urllib3/connection.py:565: in getresponse
    httplib_response = super().getresponse()
                       ^^^^^^^^^^^^^^^^^^^^^
/opt/hostedtoolcache/Python/3.11.13/x64/lib/python3.11/http/client.py:1395: in getresponse
    response.begin()
/opt/hostedtoolcache/Python/3.11.13/x64/lib/python3.11/http/client.py:325: in begin
    version, status, reason = self._read_status()
                              ^^^^^^^^^^^^^^^^^^^
/opt/hostedtoolcache/Python/3.11.13/x64/lib/python3.11/http/client.py:286: in _read_status
    line = str(self.fp.readline(_MAXLINE + 1), "iso-8859-1")
               ^^^^^^^^^^^^^^^^^^^^^^^^^^^^^^
/opt/hostedtoolcache/Python/3.11.13/x64/lib/python3.11/socket.py:718: in readinto
    return self._sock.recv_into(b)
           ^^^^^^^^^^^^^^^^^^^^^^^
E   TimeoutError: timed out

The above exception was the direct cause of the following exception:
tests/test_check_text.py:60: in test_check_center_text_after_navigation
    demoqa_page.click_elements_button()
pages/demoqa_page.py:123: in click_elements_button
    self.driver.get("https://demoqa.com/elements")
/opt/hostedtoolcache/Python/3.11.13/x64/lib/python3.11/site-packages/selenium/webdriver/remote/webdriver.py:483: in get
    self.execute(Command.GET, {"url": url})
/opt/hostedtoolcache/Python/3.11.13/x64/lib/python3.11/site-packages/selenium/webdriver/remote/webdriver.py:455: in execute
    response = cast(RemoteConnection, self.command_executor).execute(driver_command, params)
               ^^^^^^^^^^^^^^^^^^^^^^^^^^^^^^^^^^^^^^^^^^^^^^^^^^^^^^^^^^^^^^^^^^^^^^^^^^^^^
/opt/hostedtoolcache/Python/3.11.13/x64/lib/python3.11/site-packages/selenium/webdriver/remote/remote_connection.py:406: in execute
    return self._request(command_info[0], url, body=data)
           ^^^^^^^^^^^^^^^^^^^^^^^^^^^^^^^^^^^^^^^^^^^^^^
/opt/hostedtoolcache/Python/3.11.13/x64/lib/python3.11/site-packages/selenium/webdriver/remote/remote_connection.py:430: in _request
    response = self._conn.request(method, url, body=body, headers=headers, timeout=self._client_config.timeout)
               ^^^^^^^^^^^^^^^^^^^^^^^^^^^^^^^^^^^^^^^^^^^^^^^^^^^^^^^^^^^^^^^^^^^^^^^^^^^^^^^^^^^^^^^^^^^^^^^^
/opt/hostedtoolcache/Python/3.11.13/x64/lib/python3.11/site-packages/urllib3/_request_methods.py:143: in request
    return self.request_encode_body(
/opt/hostedtoolcache/Python/3.11.13/x64/lib/python3.11/site-packages/urllib3/_request_methods.py:278: in request_encode_body
    return self.urlopen(method, url, **extra_kw)
           ^^^^^^^^^^^^^^^^^^^^^^^^^^^^^^^^^^^^^
/opt/hostedtoolcache/Python/3.11.13/x64/lib/python3.11/site-packages/urllib3/poolmanager.py:459: in urlopen
    response = conn.urlopen(method, u.request_uri, **kw)
               ^^^^^^^^^^^^^^^^^^^^^^^^^^^^^^^^^^^^^^^^^
/opt/hostedtoolcache/Python/3.11.13/x64/lib/python3.11/site-packages/urllib3/connectionpool.py:841: in urlopen
    retries = retries.increment(
/opt/hostedtoolcache/Python/3.11.13/x64/lib/python3.11/site-packages/urllib3/util/retry.py:474: in increment
    raise reraise(type(error), error, _stacktrace)
          ^^^^^^^^^^^^^^^^^^^^^^^^^^^^^^^^^^^^^^^^
/opt/hostedtoolcache/Python/3.11.13/x64/lib/python3.11/site-packages/urllib3/util/util.py:39: in reraise
    raise value
/opt/hostedtoolcache/Python/3.11.13/x64/lib/python3.11/site-packages/urllib3/connectionpool.py:787: in urlopen
    response = self._make_request(
/opt/hostedtoolcache/Python/3.11.13/x64/lib/python3.11/site-packages/urllib3/connectionpool.py:536: in _make_request
    self._raise_timeout(err=e, url=url, timeout_value=read_timeout)
/opt/hostedtoolcache/Python/3.11.13/x64/lib/python3.11/site-packages/urllib3/connectionpool.py:367: in _raise_timeout
    raise ReadTimeoutError(
E   urllib3.exceptions.ReadTimeoutError: HTTPConnectionPool(host='localhost', port=59449): Read timed out. (read timeout=120)

During handling of the above exception, another exception occurred:
/opt/hostedtoolcache/Python/3.11.13/x64/lib/python3.11/site-packages/urllib3/connectionpool.py:534: in _make_request
    response = conn.getresponse()
               ^^^^^^^^^^^^^^^^^^
/opt/hostedtoolcache/Python/3.11.13/x64/lib/python3.11/site-packages/urllib3/connection.py:565: in getresponse
    httplib_response = super().getresponse()
                       ^^^^^^^^^^^^^^^^^^^^^
/opt/hostedtoolcache/Python/3.11.13/x64/lib/python3.11/http/client.py:1395: in getresponse
    response.begin()
/opt/hostedtoolcache/Python/3.11.13/x64/lib/python3.11/http/client.py:325: in begin
    version, status, reason = self._read_status()
                              ^^^^^^^^^^^^^^^^^^^
/opt/hostedtoolcache/Python/3.11.13/x64/lib/python3.11/http/client.py:286: in _read_status
    line = str(self.fp.readline(_MAXLINE + 1), "iso-8859-1")
               ^^^^^^^^^^^^^^^^^^^^^^^^^^^^^^
/opt/hostedtoolcache/Python/3.11.13/x64/lib/python3.11/socket.py:718: in readinto
    return self._sock.recv_into(b)
           ^^^^^^^^^^^^^^^^^^^^^^^
E   TimeoutError: timed out

The above exception was the direct cause of the following exception:
/opt/hostedtoolcache/Python/3.11.13/x64/lib/python3.11/site-packages/urllib3/connectionpool.py:787: in urlopen
    response = self._make_request(
/opt/hostedtoolcache/Python/3.11.13/x64/lib/python3.11/site-packages/urllib3/connectionpool.py:536: in _make_request
    self._raise_timeout(err=e, url=url, timeout_value=read_timeout)
/opt/hostedtoolcache/Python/3.11.13/x64/lib/python3.11/site-packages/urllib3/connectionpool.py:367: in _raise_timeout
    raise ReadTimeoutError(
E   urllib3.exceptions.ReadTimeoutError: HTTPConnectionPool(host='localhost', port=59449): Read timed out. (read timeout=120)

The above exception was the direct cause of the following exception:
tests/test_check_text.py:85: in test_check_center_text_after_navigation
    logger.error(f"Current URL: {driver.current_url}")
                                 ^^^^^^^^^^^^^^^^^^
/opt/hostedtoolcache/Python/3.11.13/x64/lib/python3.11/site-packages/selenium/webdriver/remote/webdriver.py:587: in current_url
    return self.execute(Command.GET_CURRENT_URL)["value"]
           ^^^^^^^^^^^^^^^^^^^^^^^^^^^^^^^^^^^^^
/opt/hostedtoolcache/Python/3.11.13/x64/lib/python3.11/site-packages/selenium/webdriver/remote/webdriver.py:455: in execute
    response = cast(RemoteConnection, self.command_executor).execute(driver_command, params)
               ^^^^^^^^^^^^^^^^^^^^^^^^^^^^^^^^^^^^^^^^^^^^^^^^^^^^^^^^^^^^^^^^^^^^^^^^^^^^^
/opt/hostedtoolcache/Python/3.11.13/x64/lib/python3.11/site-packages/selenium/webdriver/remote/remote_connection.py:406: in execute
    return self._request(command_info[0], url, body=data)
           ^^^^^^^^^^^^^^^^^^^^^^^^^^^^^^^^^^^^^^^^^^^^^^
/opt/hostedtoolcache/Python/3.11.13/x64/lib/python3.11/site-packages/selenium/webdriver/remote/remote_connection.py:430: in _request
    response = self._conn.request(method, url, body=body, headers=headers, timeout=self._client_config.timeout)
               ^^^^^^^^^^^^^^^^^^^^^^^^^^^^^^^^^^^^^^^^^^^^^^^^^^^^^^^^^^^^^^^^^^^^^^^^^^^^^^^^^^^^^^^^^^^^^^^^
/opt/hostedtoolcache/Python/3.11.13/x64/lib/python3.11/site-packages/urllib3/_request_methods.py:135: in request
    return self.request_encode_url(
/opt/hostedtoolcache/Python/3.11.13/x64/lib/python3.11/site-packages/urllib3/_request_methods.py:182: in request_encode_url
    return self.urlopen(method, url, **extra_kw)
           ^^^^^^^^^^^^^^^^^^^^^^^^^^^^^^^^^^^^^
/opt/hostedtoolcache/Python/3.11.13/x64/lib/python3.11/site-packages/urllib3/poolmanager.py:459: in urlopen
    response = conn.urlopen(method, u.request_uri, **kw)
               ^^^^^^^^^^^^^^^^^^^^^^^^^^^^^^^^^^^^^^^^^
/opt/hostedtoolcache/Python/3.11.13/x64/lib/python3.11/site-packages/urllib3/connectionpool.py:871: in urlopen
    return self.urlopen(
/opt/hostedtoolcache/Python/3.11.13/x64/lib/python3.11/site-packages/urllib3/connectionpool.py:871: in urlopen
    return self.urlopen(
/opt/hostedtoolcache/Python/3.11.13/x64/lib/python3.11/site-packages/urllib3/connectionpool.py:871: in urlopen
    return self.urlopen(
/opt/hostedtoolcache/Python/3.11.13/x64/lib/python3.11/site-packages/urllib3/connectionpool.py:841: in urlopen
    retries = retries.increment(
/opt/hostedtoolcache/Python/3.11.13/x64/lib/python3.11/site-packages/urllib3/util/retry.py:519: in increment
    raise MaxRetryError(_pool, url, reason) from reason  # type: ignore[arg-type]
    ^^^^^^^^^^^^^^^^^^^^^^^^^^^^^^^^^^^^^^^^^^^^^^^^^^^
E   urllib3.exceptions.MaxRetryError: HTTPConnectionPool(host='localhost', port=59449): Max retries exceeded with url: /session/8e51195aa1b18083d4a2013ebc4ab156/url (Caused by ReadTimeoutError("HTTPConnectionPool(host='localhost', port=59449): Read timed out. (read timeout=120)"))
2025-09-12 08:47:19,626 - conftest - INFO - Завершение работы WebDriver
